Workbook

Sheet Leads
A1: Kans | B1: Bedrijf | C1: Segment | D1: Adres | E1: Postcode | F1: Plaats | G1: Telefoon | H1: Website | I1: Google Maps | J1: Contactpersoon | K1: Functie | L1: E-mail | M1: Waarom interessant | N1: Aanpak | O1: Status | P1: Laatste contact | Q1: Volgende actie | R1: Notities | S1: LinkedIn: Warehouse manager | T1: LinkedIn: Supply chain manager | U1: LinkedIn: Crossdock manager | V1: Google: alle 3 functies | W1: Familiebedrijf
A2: A | B2: Kuehne + Nagel Logistics BV | C2: 3PL contractlogistiek | D2: Sojadijk 4-6 | E2: 5704 RL | F2: Helmond | G2: +31 492 338 338 | H2: https://www.kuehne-nagel.com/ | I2: Open in Maps | M2: Grote 3PL met veel palletbewegingen. Inkoop materieel mogelijk centraal. | N2: Direct benaderen: LinkedIn + mail met one-pager, binnen 1 week bellen | O2: Nieuw | S2: Zoek | T2: Zoek | U2: Zoek | V2: Zoek
A3: A | B3: NUNNER Logistics BV | C3: Logistiek dienstverlener / DC | D3: Gerstdijk 24 | E3: 5704 RG | F3: Helmond | G3: +31 40 204 5550 | I3: Open in Maps | M3: Groot DC (20+ docks volgens chauffeurs), lange laad-/lostijden: sterk efficiëntie-verhaal. | N3: Direct benaderen: LinkedIn + mail met one-pager, binnen 1 week bellen | O3: Nieuw | S3: Zoek | T3: Zoek | U3: Zoek | V3: Zoek
A4: A | B4: Van den Broek Logistics BV | C4: Transport & opslag | D4: Vossenbeemd 112 | E4: 5705 CL | F4: Helmond | G4: +31 492 751 400 | H4: http://www.broeklogistics.nl/ | I4: Open in Maps | M4: Transport en opslag in één, laadramps op het terrein. | N4: Direct benaderen: LinkedIn + mail met one-pager, binnen 1 week bellen | O4: Nieuw | S4: Zoek | T4: Zoek | U4: Zoek | V4: Zoek
A5: A | B5: Vos Logistics Helmond | C5: Logistiek dienstverlener / DC | D5: Haverdijk 3A | E5: 5704 RC | F5: Helmond | G5: +31 492 531 313 | H5: https://www.voslogistics.com/ | I5: Open in Maps | M5: Groot DC met veel docks, o.a. distributie voor IKEA. Zelfde groep als Vos in Oss: kans op meerdere locaties. | N5: Direct benaderen: LinkedIn + mail met one-pager, binnen 1 week bellen | O5: Nieuw | S5: Zoek | T5: Zoek | U5: Zoek | V5: Zoek
A6: A | B6: Expeditie- en Transportbedrijf Dollevoet B.V. | C6: Expeditie met warehouse | D6: Kantsingel 15 | E6: 5349 AJ | F6: Oss | G6: +31 73 521 2769 | H6: https://www.dollevoet.nl/ | I6: Open in Maps | M6: Hoofdvestiging met eigen warehouse en eigen laadpersoneel. | N6: Direct benaderen: LinkedIn + mail met one-pager, binnen 1 week bellen | O6: Nieuw | S6: Zoek | T6: Zoek | U6: Zoek | V6: Zoek
A7: A | B7: Hartog & Bikker Logistics b.v. | C7: Logistiek dienstverlener | D7: IJsselstraat 30 | E7: 5347 KG | F7: Oss | G7: +31 412 671 777 | I7: Open in Maps | M7: Klachten over dockplanning: 'sneller door het dock' past precies. | N7: Direct benaderen: LinkedIn + mail met one-pager, binnen 1 week bellen | O7: Nieuw | S7: Zoek | T7: Zoek | U7: Zoek | V7: Zoek
A8: A | B8: Vos Bulk Logistics Oss B.V. | C8: Warehouse | D8: Waalkade 13 | E8: 5347 KR | F8: Oss | G8: +31 412 699 565 | H8: http://www.voslogistics.com/ | I8: Open in Maps | M8: Warehouse met heftrucklading naast Vos Distri. | N8: Direct benaderen: LinkedIn + mail met one-pager, binnen 1 week bellen | O8: Nieuw | S8: Zoek | T8: Zoek | U8: Zoek | V8: Zoek
A9: A | B9: Vos Distri Logistics Oss | C9: Distributie | D9: Waalkade 12 | E9: 5347 KS | F9: Oss | G9: +31 412 699 301 | H9: https://www.voslogistics.com/ | I9: Open in Maps | M9: Distributie (o.a. IKEA thuisbezorging). Combineer met Vos Bulk en Vos Helmond. | N9: Direct benaderen: LinkedIn + mail met one-pager, binnen 1 week bellen | O9: Nieuw | S9: Zoek | T9: Zoek | U9: Zoek | V9: Zoek
A10: A | B10: Chain Logistics BV | C10: Opslag & distributie | D10: Jagersveld 6a | E10: 5405 BW | F10: Uden | G10: +31 88 111 5200 | H10: https://www.chain-logistics.nl/ | I10: Open in Maps | M10: Opslag en distributie met laadramps. | N10: Direct benaderen: LinkedIn + mail met one-pager, binnen 1 week bellen | O10: Nieuw | S10: Zoek | T10: Zoek | U10: Zoek | V10: Zoek
A11: A | B11: Sanders | Fritom B.V. | C11: Groupage / distributie | D11: Jagersveld 14 | E11: 5405 BW | F11: Uden | G11: +31 413 224 444 | H11: https://www.sandersfritom.nl/ | I11: Open in Maps | M11: Groupage-vervoerder met veel docks en lange werkdagen: veel crossdock-bewegingen. | N11: Direct benaderen: LinkedIn + mail met one-pager, binnen 1 week bellen | O11: Nieuw | S11: Zoek | T11: Zoek | U11: Zoek | V11: Zoek
A12: A | B12: Van den Heuvel Logistiek Uden B.V. (SVZ) | C12: Logistiek dienstverlener | D12: Erfstraat 23 | E12: 5405 BE | F12: Uden | G12: +31 413 339 933 | H12: https://svztransport.nl/ | I12: Open in Maps | M12: Onderdeel van SVZ, veel vrachtverkeer. Kans op meerdere SVZ-locaties. | N12: Direct benaderen: LinkedIn + mail met one-pager, binnen 1 week bellen | O12: Nieuw | S12: Zoek | T12: Zoek | U12: Zoek | V12: Zoek
A13: B | B13: DHL CityHub Helmond | C13: Pakket-hub / crossdock | D13: Branchweg 8 | E13: 5705 DR | F13: Helmond | H13: http://dhl.com/ | I13: Open in Maps | M13: Werkt als crossdock; inkoop materieel vaak centraal bij DHL. | N13: Eerst onderzoeken (website/LinkedIn), daarna benaderen | O13: Nieuw | S13: Zoek | T13: Zoek | U13: Zoek | V13: Zoek
A14: B | B14: EDCO Helmond | C14: Opslag & distributie | D14: Rietbeemdweg 5 | E14: 5705 BH | F14: Helmond | G14: +31 40 250 1111 | H14: http://www.edco.nl/ | I14: Open in Maps | M14: Opslag/distributie met dockplanning. | N14: Eerst onderzoeken (website/LinkedIn), daarna benaderen | O14: Nieuw | S14: Zoek | T14: Zoek | U14: Zoek | V14: Zoek
A15: B | B15: Friedi Slegers Transport & Warehousing | C15: Transport & warehousing | D15: Lagedijk 28A | E15: 5705 BZ | F15: Helmond | G15: +31 492 525 190 | H15: https://www.facebook.com/friedislegers/ | I15: Open in Maps | M15: Transport en warehousing, middelgroot. | N15: Eerst onderzoeken (website/LinkedIn), daarna benaderen | O15: Nieuw | S15: Zoek | T15: Zoek | U15: Zoek | V15: Zoek
A16: B | B16: Vegro Distributiecentrum | C16: Eigen DC (groothandel zorghulpmiddelen) | D16: Vossenbeemd 111 | E16: 5705 CL | F16: Helmond | H16: http://www.vegro.nl/ | I16: Open in Maps | M16: Eigen DC: klant beslist zelf over materieel. | N16: Eerst onderzoeken (website/LinkedIn), daarna benaderen | O16: Nieuw | S16: Zoek | T16: Zoek | U16: Zoek | V16: Zoek
A17: B | B17: Alju B.V. | C17: Transport & distributie | D17: Molenweg 93 | E17: 5349 AC | F17: Oss | G17: +31 412 745 030 | H17: http://www.alju.nl/ | I17: Open in Maps | M17: Transport en distributie. | N17: Eerst onderzoeken (website/LinkedIn), daarna benaderen | O17: Nieuw | S17: Zoek | T17: Zoek | U17: Zoek | V17: Zoek
A18: B | B18: Hospital Logistics Nederland Bv | C18: Zorglogistiek | D18: Ketelmeer 23 | E18: 5347 JX | F18: Oss | I18: Open in Maps | M18: Opslag en distributie in de zorg. | N18: Eerst onderzoeken (website/LinkedIn), daarna benaderen | O18: Nieuw | S18: Zoek | T18: Zoek | U18: Zoek | V18: Zoek
A19: B | B19: MNG Logistics | C19: Transport & opslag | D19: Kanaalstraat 41 | E19: 5347 KM | F19: Oss | G19: +31 6 52245404 | H19: https://mnglogistics.nl/ | I19: Open in Maps | M19: Transport en opslag, kleiner bedrijf. | N19: Eerst onderzoeken (website/LinkedIn), daarna benaderen | O19: Nieuw | S19: Zoek | T19: Zoek | U19: Zoek | V19: Zoek
A20: B | B20: PLUS Distributiecentrum Oss | C20: Retail-DC | D20: Keltenweg 30 | E20: 5342 LP | F20: Oss | G20: +31 88 344 6000 | H20: http://www.plus.nl/ | I20: Open in Maps | M20: Groot retail-DC, deels geautomatiseerd, lange lostijden. Langer traject via hoofdkantoor (A/B). | N20: Eerst onderzoeken (website/LinkedIn), daarna benaderen | O20: Nieuw | S20: Zoek | T20: Zoek | U20: Zoek | V20: Zoek
A21: B | B21: Transport ITC Holland BV | C21: Transport (tank) | D21: Vorstengrafdonk 71 | E21: 5342 LW | F21: Oss | G21: +31 412 664 230 | H21: http://www.itcholland.com/ | I21: Open in Maps | M21: Vooral tanktransport/cleaning; controleren of er palletwerk is. | N21: Eerst onderzoeken (website/LinkedIn), daarna benaderen | O21: Nieuw | S21: Zoek | T21: Zoek | U21: Zoek | V21: Zoek
A22: B | B22: Vice Versa | C22: Koelhuis / opslag | D22: Maaskade 13 | E22: 5347 KD | F22: Oss | H22: http://www.vice-versa.org/ | I22: Open in Maps | M22: Koelhuis: eerst geschiktheid Mek-Rider voor koel/vries controleren. | N22: Eerst onderzoeken (website/LinkedIn), daarna benaderen | O22: Nieuw | S22: Zoek | T22: Zoek | U22: Zoek | V22: Zoek
A23: B | B23: ADEZZ magazijn | C23: Eigen magazijn producent | D23: Frontstraat 3B | E23: 5405 AK | F23: Uden | I23: Open in Maps | M23: Magazijn van producent tuinproducten; lange/afwijkende pallets mogelijk. | N23: Eerst onderzoeken (website/LinkedIn), daarna benaderen | O23: Nieuw | S23: Zoek | T23: Zoek | U23: Zoek | V23: Zoek
A24: B | B24: DESTIL Uden | C24: Groothandel bouw & industrie | D24: Industrielaan 3-A | E24: 5405 AA | F24: Uden | G24: +31 413 255 055 | H24: https://www.destil.nl/over-destil/vestigingen/destil-uden | I24: Open in Maps | M24: Groothandelsvestiging; lange materialen (profielen) passen bij lange-pallet-verhaal. | N24: Eerst onderzoeken (website/LinkedIn), daarna benaderen | O24: Nieuw | S24: Zoek | T24: Zoek | U24: Zoek | V24: Zoek
A25: B | B25: Modine (magazijn Uden) | C25: Eigen magazijn producent | D25: Frontstraat 13 | E25: 5405 AK | F25: Uden | I25: Open in Maps | M25: Eigen magazijn van producent; klant beslist zelf over materieel. | N25: Eerst onderzoeken (website/LinkedIn), daarna benaderen | O25: Nieuw | S25: Zoek | T25: Zoek | U25: Zoek | V25: Zoek
A26: B | B26: Sidekix | C26: Fulfilment / e-commerce | D26: Loopkantstraat 19 | E26: 5405 NB | F26: Uden | G26: +31 88 623 7000 | H26: https://www.sidekix.nl/ | I26: Open in Maps | M26: Fulfilment voor o.a. telecom; checken hoeveel palletwerk. | N26: Eerst onderzoeken (website/LinkedIn), daarna benaderen | O26: Nieuw | S26: Zoek | T26: Zoek | U26: Zoek | V26: Zoek
A27: C | B27: Lion Logistics Oss | C27: Koerier / thuisbezorging | D27: Hunnenpad 6A | E27: 5349 BG | F27: Oss | G27: +31 412 849 123 | H27: http://www.lionlogistics.nl/ | I27: Open in Maps | M27: Weinig palletwerk; lage prioriteit. | N27: Lage prioriteit: opnemen in nieuwsbrief/later | O27: Nieuw | S27: Zoek | T27: Zoek | U27: Zoek | V27: Zoek
A28: C | B28: HUFA Logistics | C28: Meubelbezorging aan huis | D28: Loopkantstraat 25C | E28: 5405 AC | F28: Uden | G28: +31 85 401 1396 | H28: http://www.hufa-logistics.nl/ | I28: Open in Maps | M28: Thuisbezorging meubels, weinig palletwerk. | N28: Lage prioriteit: opnemen in nieuwsbrief/later | O28: Nieuw | S28: Zoek | T28: Zoek | U28: Zoek | V28: Zoek
A29: C | B29: Van Grunsven Transport | C29: Transport | D29: Bovenstraat 5 | E29: 5405 BD | F29: Uden | G29: +31 413 310 177 | H29: https://www.vangrunsventransport.nl/ | I29: Open in Maps | M29: Vooral transport; controleren of er een warehouse is. | N29: Lage prioriteit: opnemen in nieuwsbrief/later | O29: Nieuw | S29: Zoek | T29: Zoek | U29: Zoek | V29: Zoek
A30: C | B30: Transport 4u | C30: Koerier | D30: Goorkensweg 5A | E30: 5408 SC | F30: Volkel | G30: +31 413 432 011 | H30: http://www.transport-4u.nl/ | I30: Open in Maps | M30: Koerier / kleine zendingen. | N30: Lage prioriteit: opnemen in nieuwsbrief/later | O30: Nieuw | S30: Zoek | T30: Zoek | U30: Zoek | V30: Zoek
A31: A | B31: Vendrig Transport B.V. | C31: Transport & opslag | D31: Randweg 1 | E31: 5711 DJ | F31: Someren | G31: +31 493 495 937 | H31: http://www.vendrigtransport.nl/ | I31: Open in Maps | M31: Familiebedrijf met opslag en laadramps; veel vrachtverkeer. | N31: Direct benaderen: LinkedIn + mail met one-pager, binnen 1 week bellen | O31: Nieuw | S31: Zoek | T31: Zoek | U31: Zoek | V31: Zoek | W31: Ja
A32: A | B32: Gebroeders van Eijk Logistiek | C32: Logistiek / warehouse | D32: Beemdstraat 10 | E32: 5711 CV | F32: Someren | G32: +31 493 712 310 | H32: http://www.gebroedersvaneijk.nl/ | I32: Open in Maps | M32: Warehouse met ramps; zelfde familie als Gebr. van Eijk Transport Asten: één gesprek, twee locaties. | N32: Direct benaderen: LinkedIn + mail met one-pager, binnen 1 week bellen | O32: Nieuw | S32: Zoek | T32: Zoek | U32: Zoek | V32: Zoek | W32: Ja
A33: A | B33: Gebroeders van Eijk Transport | C33: Transport & logistiek | D33: Het Hoogvelt 8 | E33: 5721 VW | F33: Asten | G33: +31 493 348 880 | H33: https://www.gebroedersvaneijk.nl/ | I33: Open in Maps | M33: Hoofdvestiging Gebr. van Eijk; combineer met locatie Someren. | N33: Direct benaderen: LinkedIn + mail met one-pager, binnen 1 week bellen | O33: Nieuw | S33: Zoek | T33: Zoek | U33: Zoek | V33: Zoek | W33: Ja
A34: A | B34: van Nunen Transport & Logistiek bv | C34: Transport & opslag | D34: Spaarpot 7 | E34: 5667 KV | F34: Geldrop | G34: +31 40 286 3346 | H34: http://www.nuntrans.nl/ | I34: Open in Maps | M34: Familiebedrijf met opslag, laden en lossen. | N34: Direct benaderen: LinkedIn + mail met one-pager, binnen 1 week bellen | O34: Nieuw | S34: Zoek | T34: Zoek | U34: Zoek | V34: Zoek | W34: Ja
A35: A | B35: Driessen Vlierden Transport | C35: Transport & laden/lossen | D35: Voltstraat 5 | E35: 5753 RL | F35: Deurne | G35: +31 493 750 640 | H35: http://www.driessenvlierden.nl/ | I35: Open in Maps | M35: Veel laad- en losbewegingen aan het dock. | N35: Direct benaderen: LinkedIn + mail met one-pager, binnen 1 week bellen | O35: Nieuw | S35: Zoek | T35: Zoek | U35: Zoek | V35: Zoek | W35: Ja
A36: A | B36: Jan de Rijk Logistics (Geldrop) | C36: Warehousing & distributie | D36: De Hooge Akker 6 | E36: 5661 NG | F36: Geldrop | G36: +31 40 289 5555 | H36: http://www.janderijk.com/ | I36: Open in Maps | M36: Groot familiebedrijf met warehousing in Geldrop (2 locaties); inkoop mogelijk via hoofdkantoor. | N36: Direct benaderen: LinkedIn + mail met one-pager, binnen 1 week bellen | O36: Nieuw | S36: Zoek | T36: Zoek | U36: Zoek | V36: Zoek | W36: Ja (groot)
A37: B | B37: Manders Transport & Logistics B.V. | C37: Transport & logistiek | D37: Spaarpot Oost 4 | E37: 5667 KT | F37: Geldrop | G37: +31 40 280 9620 | H37: http://www.manderslogistics.nl/ | I37: Open in Maps | M37: Familiebedrijf; checken hoeveel warehouse-activiteit. | N37: Eerst onderzoeken (website/LinkedIn), daarna benaderen | O37: Nieuw | S37: Zoek | T37: Zoek | U37: Zoek | V37: Zoek | W37: Ja
A38: B | B38: Schneider Expeditie BV | C38: Expeditie | D38: Het Hoogvelt 12 | E38: 5721 VW | F38: Asten | G38: +31 493 671 111 | H38: http://www.schneider-transport.com/ | I38: Open in Maps | M38: Expeditie met laden/lossen en douane. | N38: Eerst onderzoeken (website/LinkedIn), daarna benaderen | O38: Nieuw | S38: Zoek | T38: Zoek | U38: Zoek | V38: Zoek | W38: Ja
A39: B | B39: Lankveld Logistics B.V. | C39: Transport & opslag | D39: Bosscheweg 40 | E39: 5741 SX | F39: Beek en Donk | G39: +31 492 465 600 | H39: https://www.lankveld.com/ | I39: Open in Maps | M39: Familiebedrijf met opslag. | N39: Eerst onderzoeken (website/LinkedIn), daarna benaderen | O39: Nieuw | S39: Zoek | T39: Zoek | U39: Zoek | V39: Zoek | W39: Ja
A40: B | B40: Van Uden - Bekx Transport B.V. | C40: Transport | D40: Bijenweg 3 | E40: 5741 SG | F40: Beek en Donk | G40: +31 492 461 528 | H40: http://www.vanudenbekxtransport.nl/ | I40: Open in Maps | M40: Transportbedrijf; checken of er een warehouse is. | N40: Eerst onderzoeken (website/LinkedIn), daarna benaderen | O40: Nieuw | S40: Zoek | T40: Zoek | U40: Zoek | V40: Zoek | W40: Ja
...

Sheet Overzicht
A1: Overzicht leads per kans en plaats
A3: Kans | B3: Helmond | C3: Oss | D3: Uden | E3: Dorpen / overig | F3: Totaal
A4: A | B4: =COUNTIFS(Leads!$A:$A,$A4,Leads!$F:$F,B$3) -> 4 | C4: =COUNTIFS(Leads!$A:$A,$A4,Leads!$F:$F,C$3) -> 4 | D4: =COUNTIFS(Leads!$A:$A,$A4,Leads!$F:$F,D$3) -> 3 | E4: =F4-B4-C4-D4 -> 6 | F4: =COUNTIF(Leads!$A:$A,$A4) -> 17
A5: B | B5: =COUNTIFS(Leads!$A:$A,$A5,Leads!$F:$F,B$3) -> 4 | C5: =COUNTIFS(Leads!$A:$A,$A5,Leads!$F:$F,C$3) -> 6 | D5: =COUNTIFS(Leads!$A:$A,$A5,Leads!$F:$F,D$3) -> 4 | E5: =F5-B5-C5-D5 -> 14 | F5: =COUNTIF(Leads!$A:$A,$A5) -> 28
A6: C | B6: =COUNTIFS(Leads!$A:$A,$A6,Leads!$F:$F,B$3) -> 0 | C6: =COUNTIFS(Leads!$A:$A,$A6,Leads!$F:$F,C$3) -> 1 | D6: =COUNTIFS(Leads!$A:$A,$A6,Leads!$F:$F,D$3) -> 2 | E6: =F6-B6-C6-D6 -> 7 | F6: =COUNTIF(Leads!$A:$A,$A6) -> 10
A7: Totaal | B7: =SUM(B4:B6) -> 8 | C7: =SUM(C4:C6) -> 11 | D7: =SUM(D4:D6) -> 9 | E7: =SUM(E4:E6) -> 27 | F7: =SUM(F4:F6) -> 55
A9: Status | B9: Aantal
A10: Nieuw | B10: =COUNTIF(Leads!$O:$O,A10) -> 55
A11: Benaderd | B11: =COUNTIF(Leads!$O:$O,A11) -> 0
A12: Geïnteresseerd | B12: =COUNTIF(Leads!$O:$O,A12) -> 0
A13: Offerte uitgebracht | B13: =COUNTIF(Leads!$O:$O,A13) -> 0
A14: Offerte gewonnen | B14: =COUNTIF(Leads!$O:$O,A14) -> 0
A15: Offerte verloren | B15: =COUNTIF(Leads!$O:$O,A15) -> 0
A16: Geen interesse | B16: =COUNTIF(Leads!$O:$O,A16) -> 0

Sheet Uitleg
A1: Uitleg leadlijst MEK-Rider
A3: Kans A | B3: Grote logistieke operatie (DC, 3PL, warehouse) met veel palletbewegingen. Direct benaderen.
A4: Kans B | B4: Interessant, maar eerst onderzoeken: kleiner, ander segment, of inkoop via hoofdkantoor.
A5: Kans C | B5: Weinig palletwerk; lage prioriteit.
A7: Gele cellen | B7: Zelf invullen: contactpersoon, functie, e-mail, status, laatste contact, volgende actie, notities.
A8: Status | B8: Kies uit de lijst. Het tabblad Overzicht telt automatisch mee.
A9: Nieuwe leads | B9: Voeg onderaan een rij toe; Kans en Status hebben een keuzelijst.
A11: Bron | B11: Bedrijfsgegevens via Google Maps (Helmond, Oss, Uden en de dorpen rond Helmond, oktober 2026). Kans-indeling is een eerste inschatting door Claude op basis van segment, omvang en openbare reviews; controleer vóór benaderen.
